Workbook

Sheet Clasificación común
A1: Clasificación común a TVN, Canal 13, Mega y Chilevisión
A2: Nivel 1 = la partición más básica. Nivel 2 = la partición más fina que los cuatro canales permiten sin supuestos. Cifras de las notas de ingresos de los EEFF (hoja 'Líneas codificadas', columnas N y O).
A4: NIVEL 1 — Básico (% de ingresos de actividades ordinarias)
A5: Canal | B5: Categoría | C5: FY2024 | D5: FY2025 | E5: H1 2025 | F5: H1 2026
A6: TVN | B6: Publicidad | C6: =IF(SUMIFS('Líneas codificadas'!$E$2:$E$49,'Líneas codificadas'!$A$2:$A$49,"TVN",'Líneas codificadas'!$B$2:$B$49,"FY2024")=0,"n.d.",SUMIFS('Líneas codificadas'!$E$2:$E$49,'Líneas codificadas'!$A$2:$A$49,"TVN",'Líneas codificadas'!$B$2:$B$49,"FY2024",'Líneas codificadas'!$N$2:$N$49,"Publicidad")/SUMIFS('Líneas codificadas'!$E$2:$E$49,'Líneas codificadas'!$A$2:$A$49,"TVN",'Líneas codificadas'!$B$2:$B$49,"FY2024")) -> 0.63528699 | D6: =IF(SUMIFS('Líneas codificadas'!$E$2:$E$49,'Líneas codificadas'!$A$2:$A$49,"TVN",'Líneas codificadas'!$B$2:$B$49,"FY2025")=0,"n.d.",SUMIFS('Líneas codificadas'!$E$2:$E$49,'Líneas codificadas'!$A$2:$A$49,"TVN",'Líneas codificadas'!$B$2:$B$49,"FY2025",'Líneas codificadas'!$N$2:$N$49,"Publicidad")/SUMIFS('Líneas codificadas'!$E$2:$E$49,'Líneas codificadas'!$A$2:$A$49,"TVN",'Líneas codificadas'!$B$2:$B$49,"FY2025")) -> 0.60080217 | E6: =IF(SUMIFS('Líneas codificadas'!$E$2:$E$49,'Líneas codificadas'!$A$2:$A$49,"TVN",'Líneas codificadas'!$B$2:$B$49,"H1 2025")=0,"n.d.",SUMIFS('Líneas codificadas'!$E$2:$E$49,'Líneas codificadas'!$A$2:$A$49,"TVN",'Líneas codificadas'!$B$2:$B$49,"H1 2025",'Líneas codificadas'!$N$2:$N$49,"Publicidad")/SUMIFS('Líneas codificadas'!$E$2:$E$49,'Líneas codificadas'!$A$2:$A$49,"TVN",'Líneas codificadas'!$B$2:$B$49,"H1 2025")) -> 0.58156218 | F6: =IF(SUMIFS('Líneas codificadas'!$E$2:$E$49,'Líneas codificadas'!$A$2:$A$49,"TVN",'Líneas codificadas'!$B$2:$B$49,"H1 2026")=0,"n.d.",SUMIFS('Líneas codificadas'!$E$2:$E$49,'Líneas codificadas'!$A$2:$A$49,"TVN",'Líneas codificadas'!$B$2:$B$49,"H1 2026",'Líneas codificadas'!$N$2:$N$49,"Publicidad")/SUMIFS('Líneas codificadas'!$E$2:$E$49,'Líneas codificadas'!$A$2:$A$49,"TVN",'Líneas codificadas'!$B$2:$B$49,"H1 2026")) -> 0.56508885
B7: Otros ingresos | C7: =IF(SUMIFS('Líneas codificadas'!$E$2:$E$49,'Líneas codificadas'!$A$2:$A$49,"TVN",'Líneas codificadas'!$B$2:$B$49,"FY2024")=0,"n.d.",SUMIFS('Líneas codificadas'!$E$2:$E$49,'Líneas codificadas'!$A$2:$A$49,"TVN",'Líneas codificadas'!$B$2:$B$49,"FY2024",'Líneas codificadas'!$N$2:$N$49,"Otros ingresos")/SUMIFS('Líneas codificadas'!$E$2:$E$49,'Líneas codificadas'!$A$2:$A$49,"TVN",'Líneas codificadas'!$B$2:$B$49,"FY2024")) -> 0.36471301 | D7: =IF(SUMIFS('Líneas codificadas'!$E$2:$E$49,'Líneas codificadas'!$A$2:$A$49,"TVN",'Líneas codificadas'!$B$2:$B$49,"FY2025")=0,"n.d.",SUMIFS('Líneas codificadas'!$E$2:$E$49,'Líneas codificadas'!$A$2:$A$49,"TVN",'Líneas codificadas'!$B$2:$B$49,"FY2025",'Líneas codificadas'!$N$2:$N$49,"Otros ingresos")/SUMIFS('Líneas codificadas'!$E$2:$E$49,'Líneas codificadas'!$A$2:$A$49,"TVN",'Líneas codificadas'!$B$2:$B$49,"FY2025")) -> 0.39919783 | E7: =IF(SUMIFS('Líneas codificadas'!$E$2:$E$49,'Líneas codificadas'!$A$2:$A$49,"TVN",'Líneas codificadas'!$B$2:$B$49,"H1 2025")=0,"n.d.",SUMIFS('Líneas codificadas'!$E$2:$E$49,'Líneas codificadas'!$A$2:$A$49,"TVN",'Líneas codificadas'!$B$2:$B$49,"H1 2025",'Líneas codificadas'!$N$2:$N$49,"Otros ingresos")/SUMIFS('Líneas codificadas'!$E$2:$E$49,'Líneas codificadas'!$A$2:$A$49,"TVN",'Líneas codificadas'!$B$2:$B$49,"H1 2025")) -> 0.41843782 | F7: =IF(SUMIFS('Líneas codificadas'!$E$2:$E$49,'Líneas codificadas'!$A$2:$A$49,"TVN",'Líneas codificadas'!$B$2:$B$49,"H1 2026")=0,"n.d.",SUMIFS('Líneas codificadas'!$E$2:$E$49,'Líneas codificadas'!$A$2:$A$49,"TVN",'Líneas codificadas'!$B$2:$B$49,"H1 2026",'Líneas codificadas'!$N$2:$N$49,"Otros ingresos")/SUMIFS('Líneas codificadas'!$E$2:$E$49,'Líneas codificadas'!$A$2:$A$49,"TVN",'Líneas codificadas'!$B$2:$B$49,"H1 2026")) -> 0.43491115
B8: Total | C8: =IF(SUMIFS('Líneas codificadas'!$E$2:$E$49,'Líneas codificadas'!$A$2:$A$49,"TVN",'Líneas codificadas'!$B$2:$B$49,"FY2024")=0,"n.d.",SUMIFS('Líneas codificadas'!$E$2:$E$49,'Líneas codificadas'!$A$2:$A$49,"TVN",'Líneas codificadas'!$B$2:$B$49,"FY2024")/SUMIFS('Líneas codificadas'!$E$2:$E$49,'Líneas codificadas'!$A$2:$A$49,"TVN",'Líneas codificadas'!$B$2:$B$49,"FY2024")) -> 1 | D8: =IF(SUMIFS('Líneas codificadas'!$E$2:$E$49,'Líneas codificadas'!$A$2:$A$49,"TVN",'Líneas codificadas'!$B$2:$B$49,"FY2025")=0,"n.d.",SUMIFS('Líneas codificadas'!$E$2:$E$49,'Líneas codificadas'!$A$2:$A$49,"TVN",'Líneas codificadas'!$B$2:$B$49,"FY2025")/SUMIFS('Líneas codificadas'!$E$2:$E$49,'Líneas codificadas'!$A$2:$A$49,"TVN",'Líneas codificadas'!$B$2:$B$49,"FY2025")) -> 1 | E8: =IF(SUMIFS('Líneas codificadas'!$E$2:$E$49,'Líneas codificadas'!$A$2:$A$49,"TVN",'Líneas codificadas'!$B$2:$B$49,"H1 2025")=0,"n.d.",SUMIFS('Líneas codificadas'!$E$2:$E$49,'Líneas codificadas'!$A$2:$A$49,"TVN",'Líneas codificadas'!$B$2:$B$49,"H1 2025")/SUMIFS('Líneas codificadas'!$E$2:$E$49,'Líneas codificadas'!$A$2:$A$49,"TVN",'Líneas codificadas'!$B$2:$B$49,"H1 2025")) -> 1 | F8: =IF(SUMIFS('Líneas codificadas'!$E$2:$E$49,'Líneas codificadas'!$A$2:$A$49,"TVN",'Líneas codificadas'!$B$2:$B$49,"H1 2026")=0,"n.d.",SUMIFS('Líneas codificadas'!$E$2:$E$49,'Líneas codificadas'!$A$2:$A$49,"TVN",'Líneas codificadas'!$B$2:$B$49,"H1 2026")/SUMIFS('Líneas codificadas'!$E$2:$E$49,'Líneas codificadas'!$A$2:$A$49,"TVN",'Líneas codificadas'!$B$2:$B$49,"H1 2026")) -> 1
A9: Canal 13 | B9: Publicidad | C9: =IF(SUMIFS('Líneas codificadas'!$E$2:$E$49,'Líneas codificadas'!$A$2:$A$49,"Canal 13",'Líneas codificadas'!$B$2:$B$49,"FY2024")=0,"n.d.",SUMIFS('Líneas codificadas'!$E$2:$E$49,'Líneas codificadas'!$A$2:$A$49,"Canal 13",'Líneas codificadas'!$B$2:$B$49,"FY2024",'Líneas codificadas'!$N$2:$N$49,"Publicidad")/SUMIFS('Líneas codificadas'!$E$2:$E$49,'Líneas codificadas'!$A$2:$A$49,"Canal 13",'Líneas codificadas'!$B$2:$B$49,"FY2024")) -> 0.75965797 | D9: =IF(SUMIFS('Líneas codificadas'!$E$2:$E$49,'Líneas codificadas'!$A$2:$A$49,"Canal 13",'Líneas codificadas'!$B$2:$B$49,"FY2025")=0,"n.d.",SUMIFS('Líneas codificadas'!$E$2:$E$49,'Líneas codificadas'!$A$2:$A$49,"Canal 13",'Líneas codificadas'!$B$2:$B$49,"FY2025",'Líneas codificadas'!$N$2:$N$49,"Publicidad")/SUMIFS('Líneas codificadas'!$E$2:$E$49,'Líneas codificadas'!$A$2:$A$49,"Canal 13",'Líneas codificadas'!$B$2:$B$49,"FY2025")) -> 0.76724611 | E9: =IF(SUMIFS('Líneas codificadas'!$E$2:$E$49,'Líneas codificadas'!$A$2:$A$49,"Canal 13",'Líneas codificadas'!$B$2:$B$49,"H1 2025")=0,"n.d.",SUMIFS('Líneas codificadas'!$E$2:$E$49,'Líneas codificadas'!$A$2:$A$49,"Canal 13",'Líneas codificadas'!$B$2:$B$49,"H1 2025",'Líneas codificadas'!$N$2:$N$49,"Publicidad")/SUMIFS('Líneas codificadas'!$E$2:$E$49,'Líneas codificadas'!$A$2:$A$49,"Canal 13",'Líneas codificadas'!$B$2:$B$49,"H1 2025")) -> 0.75688188 | F9: =IF(SUMIFS('Líneas codificadas'!$E$2:$E$49,'Líneas codificadas'!$A$2:$A$49,"Canal 13",'Líneas codificadas'!$B$2:$B$49,"H1 2026")=0,"n.d.",SUMIFS('Líneas codificadas'!$E$2:$E$49,'Líneas codificadas'!$A$2:$A$49,"Canal 13",'Líneas codificadas'!$B$2:$B$49,"H1 2026",'Líneas codificadas'!$N$2:$N$49,"Publicidad")/SUMIFS('Líneas codificadas'!$E$2:$E$49,'Líneas codificadas'!$A$2:$A$49,"Canal 13",'Líneas codificadas'!$B$2:$B$49,"H1 2026")) -> 0.70870179
B10: Otros ingresos | C10: =IF(SUMIFS('Líneas codificadas'!$E$2:$E$49,'Líneas codificadas'!$A$2:$A$49,"Canal 13",'Líneas codificadas'!$B$2:$B$49,"FY2024")=0,"n.d.",SUMIFS('Líneas codificadas'!$E$2:$E$49,'Líneas codificadas'!$A$2:$A$49,"Canal 13",'Líneas codificadas'!$B$2:$B$49,"FY2024",'Líneas codificadas'!$N$2:$N$49,"Otros ingresos")/SUMIFS('Líneas codificadas'!$E$2:$E$49,'Líneas codificadas'!$A$2:$A$49,"Canal 13",'Líneas codificadas'!$B$2:$B$49,"FY2024")) -> 0.24034203 | D10: =IF(SUMIFS('Líneas codificadas'!$E$2:$E$49,'Líneas codificadas'!$A$2:$A$49,"Canal 13",'Líneas codificadas'!$B$2:$B$49,"FY2025")=0,"n.d.",SUMIFS('Líneas codificadas'!$E$2:$E$49,'Líneas codificadas'!$A$2:$A$49,"Canal 13",'Líneas codificadas'!$B$2:$B$49,"FY2025",'Líneas codificadas'!$N$2:$N$49,"Otros ingresos")/SUMIFS('Líneas codificadas'!$E$2:$E$49,'Líneas codificadas'!$A$2:$A$49,"Canal 13",'Líneas codificadas'!$B$2:$B$49,"FY2025")) -> 0.23275389 | E10: =IF(SUMIFS('Líneas codificadas'!$E$2:$E$49,'Líneas codificadas'!$A$2:$A$49,"Canal 13",'Líneas codificadas'!$B$2:$B$49,"H1 2025")=0,"n.d.",SUMIFS('Líneas codificadas'!$E$2:$E$49,'Líneas codificadas'!$A$2:$A$49,"Canal 13",'Líneas codificadas'!$B$2:$B$49,"H1 2025",'Líneas codificadas'!$N$2:$N$49,"Otros ingresos")/SUMIFS('Líneas codificadas'!$E$2:$E$49,'Líneas codificadas'!$A$2:$A$49,"Canal 13",'Líneas codificadas'!$B$2:$B$49,"H1 2025")) -> 0.24311812 | F10: =IF(SUMIFS('Líneas codificadas'!$E$2:$E$49,'Líneas codificadas'!$A$2:$A$49,"Canal 13",'Líneas codificadas'!$B$2:$B$49,"H1 2026")=0,"n.d.",SUMIFS('Líneas codificadas'!$E$2:$E$49,'Líneas codificadas'!$A$2:$A$49,"Canal 13",'Líneas codificadas'!$B$2:$B$49,"H1 2026",'Líneas codificadas'!$N$2:$N$49,"Otros ingresos")/SUMIFS('Líneas codificadas'!$E$2:$E$49,'Líneas codificadas'!$A$2:$A$49,"Canal 13",'Líneas codificadas'!$B$2:$B$49,"H1 2026")) -> 0.29129821
B11: Total | C11: =IF(SUMIFS('Líneas codificadas'!$E$2:$E$49,'Líneas codificadas'!$A$2:$A$49,"Canal 13",'Líneas codificadas'!$B$2:$B$49,"FY2024")=0,"n.d.",SUMIFS('Líneas codificadas'!$E$2:$E$49,'Líneas codificadas'!$A$2:$A$49,"Canal 13",'Líneas codificadas'!$B$2:$B$49,"FY2024")/SUMIFS('Líneas codificadas'!$E$2:$E$49,'Líneas codificadas'!$A$2:$A$49,"Canal 13",'Líneas codificadas'!$B$2:$B$49,"FY2024")) -> 1 | D11: =IF(SUMIFS('Líneas codificadas'!$E$2:$E$49,'Líneas codificadas'!$A$2:$A$49,"Canal 13",'Líneas codificadas'!$B$2:$B$49,"FY2025")=0,"n.d.",SUMIFS('Líneas codificadas'!$E$2:$E$49,'Líneas codificadas'!$A$2:$A$49,"Canal 13",'Líneas codificadas'!$B$2:$B$49,"FY2025")/SUMIFS('Líneas codificadas'!$E$2:$E$49,'Líneas codificadas'!$A$2:$A$49,"Canal 13",'Líneas codificadas'!$B$2:$B$49,"FY2025")) -> 1 | E11: =IF(SUMIFS('Líneas codificadas'!$E$2:$E$49,'Líneas codificadas'!$A$2:$A$49,"Canal 13",'Líneas codificadas'!$B$2:$B$49,"H1 2025")=0,"n.d.",SUMIFS('Líneas codificadas'!$E$2:$E$49,'Líneas codificadas'!$A$2:$A$49,"Canal 13",'Líneas codificadas'!$B$2:$B$49,"H1 2025")/SUMIFS('Líneas codificadas'!$E$2:$E$49,'Líneas codificadas'!$A$2:$A$49,"Canal 13",'Líneas codificadas'!$B$2:$B$49,"H1 2025")) -> 1 | F11: =IF(SUMIFS('Líneas codificadas'!$E$2:$E$49,'Líneas codificadas'!$A$2:$A$49,"Canal 13",'Líneas codificadas'!$B$2:$B$49,"H1 2026")=0,"n.d.",SUMIFS('Líneas codificadas'!$E$2:$E$49,'Líneas codificadas'!$A$2:$A$49,"Canal 13",'Líneas codificadas'!$B$2:$B$49,"H1 2026")/SUMIFS('Líneas codificadas'!$E$2:$E$49,'Líneas codificadas'!$A$2:$A$49,"Canal 13",'Líneas codificadas'!$B$2:$B$49,"H1 2026")) -> 1
A12: Mega | B12: Publicidad | C12: =IF(SUMIFS('Líneas codificadas'!$E$2:$E$49,'Líneas codificadas'!$A$2:$A$49,"Mega",'Líneas codificadas'!$B$2:$B$49,"FY2024")=0,"n.d.",SUMIFS('Líneas codificadas'!$E$2:$E$49,'Líneas codificadas'!$A$2:$A$49,"Mega",'Líneas codificadas'!$B$2:$B$49,"FY2024",'Líneas codificadas'!$N$2:$N$49,"Publicidad")/SUMIFS('Líneas codificadas'!$E$2:$E$49,'Líneas codificadas'!$A$2:$A$49,"Mega",'Líneas codificadas'!$B$2:$B$49,"FY2024")) -> 0.75694926 | D12: =IF(SUMIFS('Líneas codificadas'!$E$2:$E$49,'Líneas codificadas'!$A$2:$A$49,"Mega",'Líneas codificadas'!$B$2:$B$49,"FY2025")=0,"n.d.",SUMIFS('Líneas codificadas'!$E$2:$E$49,'Líneas codificadas'!$A$2:$A$49,"Mega",'Líneas codificadas'!$B$2:$B$49,"FY2025",'Líneas codificadas'!$N$2:$N$49,"Publicidad")/SUMIFS('Líneas codificadas'!$E$2:$E$49,'Líneas codificadas'!$A$2:$A$49,"Mega",'Líneas codificadas'!$B$2:$B$49,"FY2025")) -> 0.78894747 | E12: =IF(SUMIFS('Líneas codificadas'!$E$2:$E$49,'Líneas codificadas'!$A$2:$A$49,"Mega",'Líneas codificadas'!$B$2:$B$49,"H1 2025")=0,"n.d.",SUMIFS('Líneas codificadas'!$E$2:$E$49,'Líneas codificadas'!$A$2:$A$49,"Mega",'Líneas codificadas'!$B$2:$B$49,"H1 2025",'Líneas codificadas'!$N$2:$N$49,"Publicidad")/SUMIFS('Líneas codificadas'!$E$2:$E$49,'Líneas codificadas'!$A$2:$A$49,"Mega",'Líneas codificadas'!$B$2:$B$49,"H1 2025")) -> 0.72585315 | F12: =IF(SUMIFS('Líneas codificadas'!$E$2:$E$49,'Líneas codificadas'!$A$2:$A$49,"Mega",'Líneas codificadas'!$B$2:$B$49,"H1 2026")=0,"n.d.",SUMIFS('Líneas codificadas'!$E$2:$E$49,'Líneas codificadas'!$A$2:$A$49,"Mega",'Líneas codificadas'!$B$2:$B$49,"H1 2026",'Líneas codificadas'!$N$2:$N$49,"Publicidad")/SUMIFS('Líneas codificadas'!$E$2:$E$49,'Líneas codificadas'!$A$2:$A$49,"Mega",'Líneas codificadas'!$B$2:$B$49,"H1 2026")) -> 0.82096326
B13: Otros ingresos | C13: =IF(SUMIFS('Líneas codificadas'!$E$2:$E$49,'Líneas codificadas'!$A$2:$A$49,"Mega",'Líneas codificadas'!$B$2:$B$49,"FY2024")=0,"n.d.",SUMIFS('Líneas codificadas'!$E$2:$E$49,'Líneas codificadas'!$A$2:$A$49,"Mega",'Líneas codificadas'!$B$2:$B$49,"FY2024",'Líneas codificadas'!$N$2:$N$49,"Otros ingresos")/SUMIFS('Líneas codificadas'!$E$2:$E$49,'Líneas codificadas'!$A$2:$A$49,"Mega",'Líneas codificadas'!$B$2:$B$49,"FY2024")) -> 0.24305074 | D13: =IF(SUMIFS('Líneas codificadas'!$E$2:$E$49,'Líneas codificadas'!$A$2:$A$49,"Mega",'Líneas codificadas'!$B$2:$B$49,"FY2025")=0,"n.d.",SUMIFS('Líneas codificadas'!$E$2:$E$49,'Líneas codificadas'!$A$2:$A$49,"Mega",'Líneas codificadas'!$B$2:$B$49,"FY2025",'Líneas codificadas'!$N$2:$N$49,"Otros ingresos")/SUMIFS('Líneas codificadas'!$E$2:$E$49,'Líneas codificadas'!$A$2:$A$49,"Mega",'Líneas codificadas'!$B$2:$B$49,"FY2025")) -> 0.21105253 | E13: =IF(SUMIFS('Líneas codificadas'!$E$2:$E$49,'Líneas codificadas'!$A$2:$A$49,"Mega",'Líneas codificadas'!$B$2:$B$49,"H1 2025")=0,"n.d.",SUMIFS('Líneas codificadas'!$E$2:$E$49,'Líneas codificadas'!$A$2:$A$49,"Mega",'Líneas codificadas'!$B$2:$B$49,"H1 2025",'Líneas codificadas'!$N$2:$N$49,"Otros ingresos")/SUMIFS('Líneas codificadas'!$E$2:$E$49,'Líneas codificadas'!$A$2:$A$49,"Mega",'Líneas codificadas'!$B$2:$B$49,"H1 2025")) -> 0.27414685 | F13: =IF(SUMIFS('Líneas codificadas'!$E$2:$E$49,'Líneas codificadas'!$A$2:$A$49,"Mega",'Líneas codificadas'!$B$2:$B$49,"H1 2026")=0,"n.d.",SUMIFS('Líneas codificadas'!$E$2:$E$49,'Líneas codificadas'!$A$2:$A$49,"Mega",'Líneas codificadas'!$B$2:$B$49,"H1 2026",'Líneas codificadas'!$N$2:$N$49,"Otros ingresos")/SUMIFS('Líneas codificadas'!$E$2:$E$49,'Líneas codificadas'!$A$2:$A$49,"Mega",'Líneas codificadas'!$B$2:$B$49,"H1 2026")) -> 0.17903674
B14: Total | C14: =IF(SUMIFS('Líneas codificadas'!$E$2:$E$49,'Líneas codificadas'!$A$2:$A$49,"Mega",'Líneas codificadas'!$B$2:$B$49,"FY2024")=0,"n.d.",SUMIFS('Líneas codificadas'!$E$2:$E$49,'Líneas codificadas'!$A$2:$A$49,"Mega",'Líneas codificadas'!$B$2:$B$49,"FY2024")/SUMIFS('Líneas codificadas'!$E$2:$E$49,'Líneas codificadas'!$A$2:$A$49,"Mega",'Líneas codificadas'!$B$2:$B$49,"FY2024")) -> 1 | D14: =IF(SUMIFS('Líneas codificadas'!$E$2:$E$49,'Líneas codificadas'!$A$2:$A$49,"Mega",'Líneas codificadas'!$B$2:$B$49,"FY2025")=0,"n.d.",SUMIFS('Líneas codificadas'!$E$2:$E$49,'Líneas codificadas'!$A$2:$A$49,"Mega",'Líneas codificadas'!$B$2:$B$49,"FY2025")/SUMIFS('Líneas codificadas'!$E$2:$E$49,'Líneas codificadas'!$A$2:$A$49,"Mega",'Líneas codificadas'!$B$2:$B$49,"FY2025")) -> 1 | E14: =IF(SUMIFS('Líneas codificadas'!$E$2:$E$49,'Líneas codificadas'!$A$2:$A$49,"Mega",'Líneas codificadas'!$B$2:$B$49,"H1 2025")=0,"n.d.",SUMIFS('Líneas codificadas'!$E$2:$E$49,'Líneas codificadas'!$A$2:$A$49,"Mega",'Líneas codificadas'!$B$2:$B$49,"H1 2025")/SUMIFS('Líneas codificadas'!$E$2:$E$49,'Líneas codificadas'!$A$2:$A$49,"Mega",'Líneas codificadas'!$B$2:$B$49,"H1 2025")) -> 1 | F14: =IF(SUMIFS('Líneas codificadas'!$E$2:$E$49,'Líneas codificadas'!$A$2:$A$49,"Mega",'Líneas codificadas'!$B$2:$B$49,"H1 2026")=0,"n.d.",SUMIFS('Líneas codificadas'!$E$2:$E$49,'Líneas codificadas'!$A$2:$A$49,"Mega",'Líneas codificadas'!$B$2:$B$49,"H1 2026")/SUMIFS('Líneas codificadas'!$E$2:$E$49,'Líneas codificadas'!$A$2:$A$49,"Mega",'Líneas codificadas'!$B$2:$B$49,"H1 2026")) -> 1
A15: Chilevisión | B15: Publicidad | C15: =IF(SUMIFS('Líneas codificadas'!$E$2:$E$49,'Líneas codificadas'!$A$2:$A$49,"Chilevisión",'Líneas codificadas'!$B$2:$B$49,"FY2024")=0,"n.d.",SUMIFS('Líneas codificadas'!$E$2:$E$49,'Líneas codificadas'!$A$2:$A$49,"Chilevisión",'Líneas codificadas'!$B$2:$B$49,"FY2024",'Líneas codificadas'!$N$2:$N$49,"Publicidad")/SUMIFS('Líneas codificadas'!$E$2:$E$49,'Líneas codificadas'!$A$2:$A$49,"Chilevisión",'Líneas codificadas'!$B$2:$B$49,"FY2024")) -> 0.91045902 | D15: =IF(SUMIFS('Líneas codificadas'!$E$2:$E$49,'Líneas codificadas'!$A$2:$A$49,"Chilevisión",'Líneas codificadas'!$B$2:$B$49,"FY2025")=0,"n.d.",SUMIFS('Líneas codificadas'!$E$2:$E$49,'Líneas codificadas'!$A$2:$A$49,"Chilevisión",'Líneas codificadas'!$B$2:$B$49,"FY2025",'Líneas codificadas'!$N$2:$N$49,"Publicidad")/SUMIFS('Líneas codificadas'!$E$2:$E$49,'Líneas codificadas'!$A$2:$A$49,"Chilevisión",'Líneas codificadas'!$B$2:$B$49,"FY2025")) -> 0.89632396 | E15: =IF(SUMIFS('Líneas codificadas'!$E$2:$E$49,'Líneas codificadas'!$A$2:$A$49,"Chilevisión",'Líneas codificadas'!$B$2:$B$49,"H1 2025")=0,"n.d.",SUMIFS('Líneas codificadas'!$E$2:$E$49,'Líneas codificadas'!$A$2:$A$49,"Chilevisión",'Líneas codificadas'!$B$2:$B$49,"H1 2025",'Líneas codificadas'!$N$2:$N$49,"Publicidad")/SUMIFS('Líneas codificadas'!$E$2:$E$49,'Líneas codificadas'!$A$2:$A$49,"Chilevisión",'Líneas codificadas'!$B$2:$B$49,"H1 2025")) -> 0.95082266 | F15: =IF(SUMIFS('Líneas codificadas'!$E$2:$E$49,'Líneas codificadas'!$A$2:$A$49,"Chilevisión",'Líneas codificadas'!$B$2:$B$49,"H1 2026")=0,"n.d.",SUMIFS('Líneas codificadas'!$E$2:$E$49,'Líneas codificadas'!$A$2:$A$49,"Chilevisión",'Líneas codificadas'!$B$2:$B$49,"H1 2026",'Líneas codificadas'!$N$2:$N$49,"Publicidad")/SUMIFS('Líneas codificadas'!$E$2:$E$49,'Líneas codificadas'!$A$2:$A$49,"Chilevisión",'Líneas codificadas'!$B$2:$B$49,"H1 2026")) -> 0.9089824
B16: Otros ingresos | C16: =IF(SUMIFS('Líneas codificadas'!$E$2:$E$49,'Líneas codificadas'!$A$2:$A$49,"Chilevisión",'Líneas codificadas'!$B$2:$B$49,"FY2024")=0,"n.d.",SUMIFS('Líneas codificadas'!$E$2:$E$49,'Líneas codificadas'!$A$2:$A$49,"Chilevisión",'Líneas codificadas'!$B$2:$B$49,"FY2024",'Líneas codificadas'!$N$2:$N$49,"Otros ingresos")/SUMIFS('Líneas codificadas'!$E$2:$E$49,'Líneas codificadas'!$A$2:$A$49,"Chilevisión",'Líneas codificadas'!$B$2:$B$49,"FY2024")) -> 0.089540978 | D16: =IF(SUMIFS('Líneas codificadas'!$E$2:$E$49,'Líneas codificadas'!$A$2:$A$49,"Chilevisión",'Líneas codificadas'!$B$2:$B$49,"FY2025")=0,"n.d.",SUMIFS('Líneas codificadas'!$E$2:$E$49,'Líneas codificadas'!$A$2:$A$49,"Chilevisión",'Líneas codificadas'!$B$2:$B$49,"FY2025",'Líneas codificadas'!$N$2:$N$49,"Otros ingresos")/SUMIFS('Líneas codificadas'!$E$2:$E$49,'Líneas codificadas'!$A$2:$A$49,"Chilevisión",'Líneas codificadas'!$B$2:$B$49,"FY2025")) -> 0.10367604 | E16: =IF(SUMIFS('Líneas codificadas'!$E$2:$E$49,'Líneas codificadas'!$A$2:$A$49,"Chilevisión",'Líneas codificadas'!$B$2:$B$49,"H1 2025")=0,"n.d.",SUMIFS('Líneas codificadas'!$E$2:$E$49,'Líneas codificadas'!$A$2:$A$49,"Chilevisión",'Líneas codificadas'!$B$2:$B$49,"H1 2025",'Líneas codificadas'!$N$2:$N$49,"Otros ingresos")/SUMIFS('Líneas codificadas'!$E$2:$E$49,'Líneas codificadas'!$A$2:$A$49,"Chilevisión",'Líneas codificadas'!$B$2:$B$49,"H1 2025")) -> 0.049177343 | F16: =IF(SUMIFS('Líneas codificadas'!$E$2:$E$49,'Líneas codificadas'!$A$2:$A$49,"Chilevisión",'Líneas codificadas'!$B$2:$B$49,"H1 2026")=0,"n.d.",SUMIFS('Líneas codificadas'!$E$2:$E$49,'Líneas codificadas'!$A$2:$A$49,"Chilevisión",'Líneas codificadas'!$B$2:$B$49,"H1 2026",'Líneas codificadas'!$N$2:$N$49,"Otros ingresos")/SUMIFS('Líneas codificadas'!$E$2:$E$49,'Líneas codificadas'!$A$2:$A$49,"Chilevisión",'Líneas codificadas'!$B$2:$B$49,"H1 2026")) -> 0.091017596
B17: Total | C17: =IF(SUMIFS('Líneas codificadas'!$E$2:$E$49,'Líneas codificadas'!$A$2:$A$49,"Chilevisión",'Líneas codificadas'!$B$2:$B$49,"FY2024")=0,"n.d.",SUMIFS('Líneas codificadas'!$E$2:$E$49,'Líneas codificadas'!$A$2:$A$49,"Chilevisión",'Líneas codificadas'!$B$2:$B$49,"FY2024")/SUMIFS('Líneas codificadas'!$E$2:$E$49,'Líneas codificadas'!$A$2:$A$49,"Chilevisión",'Líneas codificadas'!$B$2:$B$49,"FY2024")) -> 1 | D17: =IF(SUMIFS('Líneas codificadas'!$E$2:$E$49,'Líneas codificadas'!$A$2:$A$49,"Chilevisión",'Líneas codificadas'!$B$2:$B$49,"FY2025")=0,"n.d.",SUMIFS('Líneas codificadas'!$E$2:$E$49,'Líneas codificadas'!$A$2:$A$49,"Chilevisión",'Líneas codificadas'!$B$2:$B$49,"FY2025")/SUMIFS('Líneas codificadas'!$E$2:$E$49,'Líneas codificadas'!$A$2:$A$49,"Chilevisión",'Líneas codificadas'!$B$2:$B$49,"FY2025")) -> 1 | E17: =IF(SUMIFS('Líneas codificadas'!$E$2:$E$49,'Líneas codificadas'!$A$2:$A$49,"Chilevisión",'Líneas codificadas'!$B$2:$B$49,"H1 2025")=0,"n.d.",SUMIFS('Líneas codificadas'!$E$2:$E$49,'Líneas codificadas'!$A$2:$A$49,"Chilevisión",'Líneas codificadas'!$B$2:$B$49,"H1 2025")/SUMIFS('Líneas codificadas'!$E$2:$E$49,'Líneas codificadas'!$A$2:$A$49,"Chilevisión",'Líneas codificadas'!$B$2:$B$49,"H1 2025")) -> 1 | F17: =IF(SUMIFS('Líneas codificadas'!$E$2:$E$49,'Líneas codificadas'!$A$2:$A$49,"Chilevisión",'Líneas codificadas'!$B$2:$B$49,"H1 2026")=0,"n.d.",SUMIFS('Líneas codificadas'!$E$2:$E$49,'Líneas codificadas'!$A$2:$A$49,"Chilevisión",'Líneas codificadas'!$B$2:$B$49,"H1 2026")/SUMIFS('Líneas codificadas'!$E$2:$E$49,'Líneas codificadas'!$A$2:$A$49,"Chilevisión",'Líneas codificadas'!$B$2:$B$49,"H1 2026")) -> 1
A19: NIVEL 2 — Común máximo (% de ingresos de actividades ordinarias)
A20: Canal | B20: Categoría | C20: FY2024 | D20: FY2025 | E20: H1 2025 | F20: H1 2026
A21: TVN | B21: Publicidad | C21: =IF(SUMIFS('Líneas codificadas'!$E$2:$E$49,'Líneas codificadas'!$A$2:$A$49,"TVN",'Líneas codificadas'!$B$2:$B$49,"FY2024")=0,"n.d.",SUMIFS('Líneas codificadas'!$E$2:$E$49,'Líneas codificadas'!$A$2:$A$49,"TVN",'Líneas codificadas'!$B$2:$B$49,"FY2024",'Líneas codificadas'!$O$2:$O$49,"Publicidad")/SUMIFS('Líneas codificadas'!$E$2:$E$49,'Líneas codificadas'!$A$2:$A$49,"TVN",'Líneas codificadas'!$B$2:$B$49,"FY2024")) -> 0.63528699 | D21: =IF(SUMIFS('Líneas codificadas'!$E$2:$E$49,'Líneas codificadas'!$A$2:$A$49,"TVN",'Líneas codificadas'!$B$2:$B$49,"FY2025")=0,"n.d.",SUMIFS('Líneas codificadas'!$E$2:$E$49,'Líneas codificadas'!$A$2:$A$49,"TVN",'Líneas codificadas'!$B$2:$B$49,"FY2025",'Líneas codificadas'!$O$2:$O$49,"Publicidad")/SUMIFS('Líneas codificadas'!$E$2:$E$49,'Líneas codificadas'!$A$2:$A$49,"TVN",'Líneas codificadas'!$B$2:$B$49,"FY2025")) -> 0.60080217 | E21: =IF(SUMIFS('Líneas codificadas'!$E$2:$E$49,'Líneas codificadas'!$A$2:$A$49,"TVN",'Líneas codificadas'!$B$2:$B$49,"H1 2025")=0,"n.d.",SUMIFS('Líneas codificadas'!$E$2:$E$49,'Líneas codificadas'!$A$2:$A$49,"TVN",'Líneas codificadas'!$B$2:$B$49,"H1 2025",'Líneas codificadas'!$O$2:$O$49,"Publicidad")/SUMIFS('Líneas codificadas'!$E$2:$E$49,'Líneas codificadas'!$A$2:$A$49,"TVN",'Líneas codificadas'!$B$2:$B$49,"H1 2025")) -> 0.58156218 | F21: =IF(SUMIFS('Líneas codificadas'!$E$2:$E$49,'Líneas codificadas'!$A$2:$A$49,"TVN",'Líneas codificadas'!$B$2:$B$49,"H1 2026")=0,"n.d.",SUMIFS('Líneas codificadas'!$E$2:$E$49,'Líneas codificadas'!$A$2:$A$49,"TVN",'Líneas codificadas'!$B$2:$B$49,"H1 2026",'Líneas codificadas'!$O$2:$O$49,"Publicidad")/SUMIFS('Líneas codificadas'!$E$2:$E$49,'Líneas codificadas'!$A$2:$A$49,"TVN",'Líneas codificadas'!$B$2:$B$49,"H1 2026")) -> 0.56508885
B22: Otros ingresos operacionales | C22: =IF(SUMIFS('Líneas codificadas'!$E$2:$E$49,'Líneas codificadas'!$A$2:$A$49,"TVN",'Líneas codificadas'!$B$2:$B$49,"FY2024")=0,"n.d.",SUMIFS('Líneas codificadas'!$E$2:$E$49,'Líneas codificadas'!$A$2:$A$49,"TVN",'Líneas codificadas'!$B$2:$B$49,"FY2024",'Líneas codificadas'!$O$2:$O$49,"Otros ingresos operacionales")/SUMIFS('Líneas codificadas'!$E$2:$E$49,'Líneas codificadas'!$A$2:$A$49,"TVN",'Líneas codificadas'!$B$2:$B$49,"FY2024")) -> 0.36471301 | D22: =IF(SUMIFS('Líneas codificadas'!$E$2:$E$49,'Líneas codificadas'!$A$2:$A$49,"TVN",'Líneas codificadas'!$B$2:$B$49,"FY2025")=0,"n.d.",SUMIFS('Líneas codificadas'!$E$2:$E$49,'Líneas codificadas'!$A$2:$A$49,"TVN",'Líneas codificadas'!$B$2:$B$49,"FY2025",'Líneas codificadas'!$O$2:$O$49,"Otros ingresos operacionales")/SUMIFS('Líneas codificadas'!$E$2:$E$49,'Líneas codificadas'!$A$2:$A$49,"TVN",'Líneas codificadas'!$B$2:$B$49,"FY2025")) -> 0.3574576 | E22: =IF(SUMIFS('Líneas codificadas'!$E$2:$E$49,'Líneas codificadas'!$A$2:$A$49,"TVN",'Líneas codificadas'!$B$2:$B$49,"H1 2025")=0,"n.d.",SUMIFS('Líneas codificadas'!$E$2:$E$49,'Líneas codificadas'!$A$2:$A$49,"TVN",'Líneas codificadas'!$B$2:$B$49,"H1 2025",'Líneas codificadas'!$O$2:$O$49,"Otros ingresos operacionales")/SUMIFS('Líneas codificadas'!$E$2:$E$49,'Líneas codificadas'!$A$2:$A$49,"TVN",'Líneas codificadas'!$B$2:$B$49,"H1 2025")) -> 0.33592015 | F22: =IF(SUMIFS('Líneas codificadas'!$E$2:$E$49,'Líneas codificadas'!$A$2:$A$49,"TVN",'Líneas codificadas'!$B$2:$B$49,"H1 2026")=0,"n.d.",SUMIFS('Líneas codificadas'!$E$2:$E$49,'Líneas codificadas'!$A$2:$A$49,"TVN",'Líneas codificadas'!$B$2:$B$49,"H1 2026",'Líneas codificadas'!$O$2:$O$49,"Otros ingresos operacionales")/SUMIFS('Líneas codificadas'!$E$2:$E$49,'Líneas codificadas'!$A$2:$A$49,"TVN",'Líneas codificadas'!$B$2:$B$49,"H1 2026")) -> 0.35848105
B23: Transferencias del Estado | C23: =IF(SUMIFS('Líneas codificadas'!$E$2:$E$49,'Líneas codificadas'!$A$2:$A$49,"TVN",'Líneas codificadas'!$B$2:$B$49,"FY2024")=0,"n.d.",SUMIFS('Líneas codificadas'!$E$2:$E$49,'Líneas codificadas'!$A$2:$A$49,"TVN",'Líneas codificadas'!$B$2:$B$49,"FY2024",'Líneas codificadas'!$O$2:$O$49,"Transferencias del Estado")/SUMIFS('Líneas codificadas'!$E$2:$E$49,'Líneas codificadas'!$A$2:$A$49,"TVN",'Líneas codificadas'!$B$2:$B$49,"FY2024")) -> 0 | D23: =IF(SUMIFS('Líneas codificadas'!$E$2:$E$49,'Líneas codificadas'!$A$2:$A$49,"TVN",'Líneas codificadas'!$B$2:$B$49,"FY2025")=0,"n.d.",SUMIFS('Líneas codificadas'!$E$2:$E$49,'Líneas codificadas'!$A$2:$A$49,"TVN",'Líneas codificadas'!$B$2:$B$49,"FY2025",'Líneas codificadas'!$O$2:$O$49,"Transferencias del Estado")/SUMIFS('Líneas codificadas'!$E$2:$E$49,'Líneas codificadas'!$A$2:$A$49,"TVN",'Líneas codificadas'!$B$2:$B$49,"FY2025")) -> 0.041740236 | E23: =IF(SUMIFS('Líneas codificadas'!$E$2:$E$49,'Líneas codificadas'!$A$2:$A$49,"TVN",'Líneas codificadas'!$B$2:$B$49,"H1 2025")=0,"n.d.",SUMIFS('Líneas codificadas'!$E$2:$E$49,'Líneas codificadas'!$A$2:$A$49,"TVN",'Líneas codificadas'!$B$2:$B$49,"H1 2025",'Líneas codificadas'!$O$2:$O$49,"Transferencias del Estado")/SUMIFS('Líneas codificadas'!$E$2:$E$49,'Líneas codificadas'!$A$2:$A$49,"TVN",'Líneas codificadas'!$B$2:$B$49,"H1 2025")) -> 0.08251767 | F23: =IF(SUMIFS('Líneas codificadas'!$E$2:$E$49,'Líneas codificadas'!$A$2:$A$49,"TVN",'Líneas codificadas'!$B$2:$B$49,"H1 2026")=0,"n.d.",SUMIFS('Líneas codificadas'!$E$2:$E$49,'Líneas codificadas'!$A$2:$A$49,"TVN",'Líneas codificadas'!$B$2:$B$49,"H1 2026",'Líneas codificadas'!$O$2:$O$49,"Transferencias del Estado")/SUMIFS('Líneas codificadas'!$E$2:$E$49,'Líneas codificadas'!$A$2:$A$49,"TVN",'Líneas codificadas'!$B$2:$B$49,"H1 2026")) -> 0.076430101
B24: Total | C24: =IF(SUMIFS('Líneas codificadas'!$E$2:$E$49,'Líneas codificadas'!$A$2:$A$49,"TVN",'Líneas codificadas'!$B$2:$B$49,"FY2024")=0,"n.d.",SUMIFS('Líneas codificadas'!$E$2:$E$49,'Líneas codificadas'!$A$2:$A$49,"TVN",'Líneas codificadas'!$B$2:$B$49,"FY2024")/SUMIFS('Líneas codificadas'!$E$2:$E$49,'Líneas codificadas'!$A$2:$A$49,"TVN",'Líneas codificadas'!$B$2:$B$49,"FY2024")) -> 1 | D24: =IF(SUMIFS('Líneas codificadas'!$E$2:$E$49,'Líneas codificadas'!$A$2:$A$49,"TVN",'Líneas codificadas'!$B$2:$B$49,"FY2025")=0,"n.d.",SUMIFS('Líneas codificadas'!$E$2:$E$49,'Líneas codificadas'!$A$2:$A$49,"TVN",'Líneas codificadas'!$B$2:$B$49,"FY2025")/SUMIFS('Líneas codificadas'!$E$2:$E$49,'Líneas codificadas'!$A$2:$A$49,"TVN",'Líneas codificadas'!$B$2:$B$49,"FY2025")) -> 1 | E24: =IF(SUMIFS('Líneas codificadas'!$E$2:$E$49,'Líneas codificadas'!$A$2:$A$49,"TVN",'Líneas codificadas'!$B$2:$B$49,"H1 2025")=0,"n.d.",SUMIFS('Líneas codificadas'!$E$2:$E$49,'Líneas codificadas'!$A$2:$A$49,"TVN",'Líneas codificadas'!$B$2:$B$49,"H1 2025")/SUMIFS('Líneas codificadas'!$E$2:$E$49,'Líneas codificadas'!$A$2:$A$49,"TVN",'Líneas codificadas'!$B$2:$B$49,"H1 2025")) -> 1 | F24: =IF(SUMIFS('Líneas codificadas'!$E$2:$E$49,'Líneas codificadas'!$A$2:$A$49,"TVN",'Líneas codificadas'!$B$2:$B$49,"H1 2026")=0,"n.d.",SUMIFS('Líneas codificadas'!$E$2:$E$49,'Líneas codificadas'!$A$2:$A$49,"TVN",'Líneas codificadas'!$B$2:$B$49,"H1 2026")/SUMIFS('Líneas codificadas'!$E$2:$E$49,'Líneas codificadas'!$A$2:$A$49,"TVN",'Líneas codificadas'!$B$2:$B$49,"H1 2026")) -> 1
A25: Canal 13 | B25: Publicidad | C25: =IF(SUMIFS('Líneas codificadas'!$E$2:$E$49,'Líneas codificadas'!$A$2:$A$49,"Canal 13",'Líneas codificadas'!$B$2:$B$49,"FY2024")=0,"n.d.",SUMIFS('Líneas codificadas'!$E$2:$E$49,'Líneas codificadas'!$A$2:$A$49,"Canal 13",'Líneas codificadas'!$B$2:$B$49,"FY2024",'Líneas codificadas'!$O$2:$O$49,"Publicidad")/SUMIFS('Líneas codificadas'!$E$2:$E$49,'Líneas codificadas'!$A$2:$A$49,"Canal 13",'Líneas codificadas'!$B$2:$B$49,"FY2024")) -> 0.75965797 | D25: =IF(SUMIFS('Líneas codificadas'!$E$2:$E$49,'Líneas codificadas'!$A$2:$A$49,"Canal 13",'Líneas codificadas'!$B$2:$B$49,"FY2025")=0,"n.d.",SUMIFS('Líneas codificadas'!$E$2:$E$49,'Líneas codificadas'!$A$2:$A$49,"Canal 13",'Líneas codificadas'!$B$2:$B$49,"FY2025",'Líneas codificadas'!$O$2:$O$49,"Publicidad")/SUMIFS('Líneas codificadas'!$E$2:$E$49,'Líneas codificadas'!$A$2:$A$49,"Canal 13",'Líneas codificadas'!$B$2:$B$49,"FY2025")) -> 0.76724611 | E25: =IF(SUMIFS('Líneas codificadas'!$E$2:$E$49,'Líneas codificadas'!$A$2:$A$49,"Canal 13",'Líneas codificadas'!$B$2:$B$49,"H1 2025")=0,"n.d.",SUMIFS('Líneas codificadas'!$E$2:$E$49,'Líneas codificadas'!$A$2:$A$49,"Canal 13",'Líneas codificadas'!$B$2:$B$49,"H1 2025",'Líneas codificadas'!$O$2:$O$49,"Publicidad")/SUMIFS('Líneas codificadas'!$E$2:$E$49,'Líneas codificadas'!$A$2:$A$49,"Canal 13",'Líneas codificadas'!$B$2:$B$49,"H1 2025")) -> 0.75688188 | F25: =IF(SUMIFS('Líneas codificadas'!$E$2:$E$49,'Líneas codificadas'!$A$2:$A$49,"Canal 13",'Líneas codificadas'!$B$2:$B$49,"H1 2026")=0,"n.d.",SUMIFS('Líneas codificadas'!$E$2:$E$49,'Líneas codificadas'!$A$2:$A$49,"Canal 13",'Líneas codificadas'!$B$2:$B$49,"H1 2026",'Líneas codificadas'!$O$2:$O$49,"Publicidad")/SUMIFS('Líneas codificadas'!$E$2:$E$49,'Líneas codificadas'!$A$2:$A$49,"Canal 13",'Líneas codificadas'!$B$2:$B$49,"H1 2026")) -> 0.70870179
B26: Otros ingresos operacionales | C26: =IF(SUMIFS('Líneas codificadas'!$E$2:$E$49,'Líneas codificadas'!$A$2:$A$49,"Canal 13",'Líneas codificadas'!$B$2:$B$49,"FY2024")=0,"n.d.",SUMIFS('Líneas codificadas'!$E$2:$E$49,'Líneas codificadas'!$A$2:$A$49,"Canal 13",'Líneas codificadas'!$B$2:$B$49,"FY2024",'Líneas codificadas'!$O$2:$O$49,"Otros ingresos operacionales")/SUMIFS('Líneas codificadas'!$E$2:$E$49,'Líneas codificadas'!$A$2:$A$49,"Canal 13",'Líneas codificadas'!$B$2:$B$49,"FY2024")) -> 0.24034203 | D26: =IF(SUMIFS('Líneas codificadas'!$E$2:$E$49,'Líneas codificadas'!$A$2:$A$49,"Canal 13",'Líneas codificadas'!$B$2:$B$49,"FY2025")=0,"n.d.",SUMIFS('Líneas codificadas'!$E$2:$E$49,'Líneas codificadas'!$A$2:$A$49,"Canal 13",'Líneas codificadas'!$B$2:$B$49,"FY2025",'Líneas codificadas'!$O$2:$O$49,"Otros ingresos operacionales")/SUMIFS('Líneas codificadas'!$E$2:$E$49,'Líneas codificadas'!$A$2:$A$49,"Canal 13",'Líneas codificadas'!$B$2:$B$49,"FY2025")) -> 0.23275389 | E26: =IF(SUMIFS('Líneas codificadas'!$E$2:$E$49,'Líneas codificadas'!$A$2:$A$49,"Canal 13",'Líneas codificadas'!$B$2:$B$49,"H1 2025")=0,"n.d.",SUMIFS('Líneas codificadas'!$E$2:$E$49,'Líneas codificadas'!$A$2:$A$49,"Canal 13",'Líneas codificadas'!$B$2:$B$49,"H1 2025",'Líneas codificadas'!$O$2:$O$49,"Otros ingresos operacionales")/SUMIFS('Líneas codificadas'!$E$2:$E$49,'Líneas codificadas'!$A$2:$A$49,"Canal 13",'Líneas codificadas'!$B$2:$B$49,"H1 2025")) -> 0.24311812 | F26: =IF(SUMIFS('Líneas codificadas'!$E$2:$E$49,'Líneas codificadas'!$A$2:$A$49,"Canal 13",'Líneas codificadas'!$B$2:$B$49,"H1 2026")=0,"n.d.",SUMIFS('Líneas codificadas'!$E$2:$E$49,'Líneas codificadas'!$A$2:$A$49,"Canal 13",'Líneas codificadas'!$B$2:$B$49,"H1 2026",'Líneas codificadas'!$O$2:$O$49,"Otros ingresos operacionales")/SUMIFS('Líneas codificadas'!$E$2:$E$49,'Líneas codificadas'!$A$2:$A$49,"Canal 13",'Líneas codificadas'!$B$2:$B$49,"H1 2026")) -> 0.29129821
B27: Transferencias del Estado | C27: =IF(SUMIFS('Líneas codificadas'!$E$2:$E$49,'Líneas codificadas'!$A$2:$A$49,"Canal 13",'Líneas codificadas'!$B$2:$B$49,"FY2024")=0,"n.d.",SUMIFS('Líneas codificadas'!$E$2:$E$49,'Líneas codificadas'!$A$2:$A$49,"Canal 13",'Líneas codificadas'!$B$2:$B$49,"FY2024",'Líneas codificadas'!$O$2:$O$49,"Transferencias del Estado")/SUMIFS('Líneas codificadas'!$E$2:$E$49,'Líneas codificadas'!$A$2:$A$49,"Canal 13",'Líneas codificadas'!$B$2:$B$49,"FY2024")) -> 0 | D27: =IF(SUMIFS('Líneas codificadas'!$E$2:$E$49,'Líneas codificadas'!$A$2:$A$49,"Canal 13",'Líneas codificadas'!$B$2:$B$49,"FY2025")=0,"n.d.",SUMIFS('Líneas codificadas'!$E$2:$E$49,'Líneas codificadas'!$A$2:$A$49,"Canal 13",'Líneas codificadas'!$B$2:$B$49,"FY2025",'Líneas codificadas'!$O$2:$O$49,"Transferencias del Estado")/SUMIFS('Líneas codificadas'!$E$2:$E$49,'Líneas codificadas'!$A$2:$A$49,"Canal 13",'Líneas codificadas'!$B$2:$B$49,"FY2025")) -> 0 | E27: =IF(SUMIFS('Líneas codificadas'!$E$2:$E$49,'Líneas codificadas'!$A$2:$A$49,"Canal 13",'Líneas codificadas'!$B$2:$B$49,"H1 2025")=0,"n.d.",SUMIFS('Líneas codificadas'!$E$2:$E$49,'Líneas codificadas'!$A$2:$A$49,"Canal 13",'Líneas codificadas'!$B$2:$B$49,"H1 2025",'Líneas codificadas'!$O$2:$O$49,"Transferencias del Estado")/SUMIFS('Líneas codificadas'!$E$2:$E$49,'Líneas codificadas'!$A$2:$A$49,"Canal 13",'Líneas codificadas'!$B$2:$B$49,"H1 2025")) -> 0 | F27: =IF(SUMIFS('Líneas codificadas'!$E$2:$E$49,'Líneas codificadas'!$A$2:$A$49,"Canal 13",'Líneas codificadas'!$B$2:$B$49,"H1 2026")=0,"n.d.",SUMIFS('Líneas codificadas'!$E$2:$E$49,'Líneas codificadas'!$A$2:$A$49,"Canal 13",'Líneas codificadas'!$B$2:$B$49,"H1 2026",'Líneas codificadas'!$O$2:$O$49,"Transferencias del Estado")/SUMIFS('Líneas codificadas'!$E$2:$E$49,'Líneas codificadas'!$A$2:$A$49,"Canal 13",'Líneas codificadas'!$B$2:$B$49,"H1 2026")) -> 0
B28: Total | C28: =IF(SUMIFS('Líneas codificadas'!$E$2:$E$49,'Líneas codificadas'!$A$2:$A$49,"Canal 13",'Líneas codificadas'!$B$2:$B$49,"FY2024")=0,"n.d.",SUMIFS('Líneas codificadas'!$E$2:$E$49,'Líneas codificadas'!$A$2:$A$49,"Canal 13",'Líneas codificadas'!$B$2:$B$49,"FY2024")/SUMIFS('Líneas codificadas'!$E$2:$E$49,'Líneas codificadas'!$A$2:$A$49,"Canal 13",'Líneas codificadas'!$B$2:$B$49,"FY2024")) -> 1 | D28: =IF(SUMIFS('Líneas codificadas'!$E$2:$E$49,'Líneas codificadas'!$A$2:$A$49,"Canal 13",'Líneas codificadas'!$B$2:$B$49,"FY2025")=0,"n.d.",SUMIFS('Líneas codificadas'!$E$2:$E$49,'Líneas codificadas'!$A$2:$A$49,"Canal 13",'Líneas codificadas'!$B$2:$B$49,"FY2025")/SUMIFS('Líneas codificadas'!$E$2:$E$49,'Líneas codificadas'!$A$2:$A$49,"Canal 13",'Líneas codificadas'!$B$2:$B$49,"FY2025")) -> 1 | E28: =IF(SUMIFS('Líneas codificadas'!$E$2:$E$49,'Líneas codificadas'!$A$2:$A$49,"Canal 13",'Líneas codificadas'!$B$2:$B$49,"H1 2025")=0,"n.d.",SUMIFS('Líneas codificadas'!$E$2:$E$49,'Líneas codificadas'!$A$2:$A$49,"Canal 13",'Líneas codificadas'!$B$2:$B$49,"H1 2025")/SUMIFS('Líneas codificadas'!$E$2:$E$49,'Líneas codificadas'!$A$2:$A$49,"Canal 13",'Líneas codificadas'!$B$2:$B$49,"H1 2025")) -> 1 | F28: =IF(SUMIFS('Líneas codificadas'!$E$2:$E$49,'Líneas codificadas'!$A$2:$A$49,"Canal 13",'Líneas codificadas'!$B$2:$B$49,"H1 2026")=0,"n.d.",SUMIFS('Líneas codificadas'!$E$2:$E$49,'Líneas codificadas'!$A$2:$A$49,"Canal 13",'Líneas codificadas'!$B$2:$B$49,"H1 2026")/SUMIFS('Líneas codificadas'!$E$2:$E$49,'Líneas codificadas'!$A$2:$A$49,"Canal 13",'Líneas codificadas'!$B$2:$B$49,"H1 2026")) -> 1
A29: Mega | B29: Publicidad | C29: =IF(SUMIFS('Líneas codificadas'!$E$2:$E$49,'Líneas codificadas'!$A$2:$A$49,"Mega",'Líneas codificadas'!$B$2:$B$49,"FY2024")=0,"n.d.",SUMIFS('Líneas codificadas'!$E$2:$E$49,'Líneas codificadas'!$A$2:$A$49,"Mega",'Líneas codificadas'!$B$2:$B$49,"FY2024",'Líneas codificadas'!$O$2:$O$49,"Publicidad")/SUMIFS('Líneas codificadas'!$E$2:$E$49,'Líneas codificadas'!$A$2:$A$49,"Mega",'Líneas codificadas'!$B$2:$B$49,"FY2024")) -> 0.75694926 | D29: =IF(SUMIFS('Líneas codificadas'!$E$2:$E$49,'Líneas codificadas'!$A$2:$A$49,"Mega",'Líneas codificadas'!$B$2:$B$49,"FY2025")=0,"n.d.",SUMIFS('Líneas codificadas'!$E$2:$E$49,'Líneas codificadas'!$A$2:$A$49,"Mega",'Líneas codificadas'!$B$2:$B$49,"FY2025",'Líneas codificadas'!$O$2:$O$49,"Publicidad")/SUMIFS('Líneas codificadas'!$E$2:$E$49,'Líneas codificadas'!$A$2:$A$49,"Mega",'Líneas codificadas'!$B$2:$B$49,"FY2025")) -> 0.78894747 | E29: =IF(SUMIFS('Líneas codificadas'!$E$2:$E$49,'Líneas codificadas'!$A$2:$A$49,"Mega",'Líneas codificadas'!$B$2:$B$49,"H1 2025")=0,"n.d.",SUMIFS('Líneas codificadas'!$E$2:$E$49,'Líneas codificadas'!$A$2:$A$49,"Mega",'Líneas codificadas'!$B$2:$B$49,"H1 2025",'Líneas codificadas'!$O$2:$O$49,"Publicidad")/SUMIFS('Líneas codificadas'!$E$2:$E$49,'Líneas codificadas'!$A$2:$A$49,"Mega",'Líneas codificadas'!$B$2:$B$49,"H1 2025")) -> 0.72585315 | F29: =IF(SUMIFS('Líneas codificadas'!$E$2:$E$49,'Líneas codificadas'!$A$2:$A$49,"Mega",'Líneas codificadas'!$B$2:$B$49,"H1 2026")=0,"n.d.",SUMIFS('Líneas codificadas'!$E$2:$E$49,'Líneas codificadas'!$A$2:$A$49,"Mega",'Líneas codificadas'!$B$2:$B$49,"H1 2026",'Líneas codificadas'!$O$2:$O$49,"Publicidad")/SUMIFS('Líneas codificadas'!$E$2:$E$49,'Líneas codificadas'!$A$2:$A$49,"Mega",'Líneas codificadas'!$B$2:$B$49,"H1 2026")) -> 0.82096326
B30: Otros ingresos operacionales | C30: =IF(SUMIFS('Líneas codificadas'!$E$2:$E$49,'Líneas codificadas'!$A$2:$A$49,"Mega",'Líneas codificadas'!$B$2:$B$49,"FY2024")=0,"n.d.",SUMIFS('Líneas codificadas'!$E$2:$E$49,'Líneas codificadas'!$A$2:$A$49,"Mega",'Líneas codificadas'!$B$2:$B$49,"FY2024",'Líneas codificadas'!$O$2:$O$49,"Otros ingresos operacionales")/SUMIFS('Líneas codificadas'!$E$2:$E$49,'Líneas codificadas'!$A$2:$A$49,"Mega",'Líneas codificadas'!$B$2:$B$49,"FY2024")) -> 0.24305074 | D30: =IF(SUMIFS('Líneas codificadas'!$E$2:$E$49,'Líneas codificadas'!$A$2:$A$49,"Mega",'Líneas codificadas'!$B$2:$B$49,"FY2025")=0,"n.d.",SUMIFS('Líneas codificadas'!$E$2:$E$49,'Líneas codificadas'!$A$2:$A$49,"Mega",'Líneas codificadas'!$B$2:$B$49,"FY2025",'Líneas codificadas'!$O$2:$O$49,"Otros ingresos operacionales")/SUMIFS('Líneas codificadas'!$E$2:$E$49,'Líneas codificadas'!$A$2:$A$49,"Mega",'Líneas codificadas'!$B$2:$B$49,"FY2025")) -> 0.21105253 | E30: =IF(SUMIFS('Líneas codificadas'!$E$2:$E$49,'Líneas codificadas'!$A$2:$A$49,"Mega",'Líneas codificadas'!$B$2:$B$49,"H1 2025")=0,"n.d.",SUMIFS('Líneas codificadas'!$E$2:$E$49,'Líneas codificadas'!$A$2:$A$49,"Mega",'Líneas codificadas'!$B$2:$B$49,"H1 2025",'Líneas codificadas'!$O$2:$O$49,"Otros ingresos operacionales")/SUMIFS('Líneas codificadas'!$E$2:$E$49,'Líneas codificadas'!$A$2:$A$49,"Mega",'Líneas codificadas'!$B$2:$B$49,"H1 2025")) -> 0.27414685 | F30: =IF(SUMIFS('Líneas codificadas'!$E$2:$E$49,'Líneas codificadas'!$A$2:$A$49,"Mega",'Líneas codificadas'!$B$2:$B$49,"H1 2026")=0,"n.d.",SUMIFS('Líneas codificadas'!$E$2:$E$49,'Líneas codificadas'!$A$2:$A$49,"Mega",'Líneas codificadas'!$B$2:$B$49,"H1 2026",'Líneas codificadas'!$O$2:$O$49,"Otros ingresos operacionales")/SUMIFS('Líneas codificadas'!$E$2:$E$49,'Líneas codificadas'!$A$2:$A$49,"Mega",'Líneas codificadas'!$B$2:$B$49,"H1 2026")) -> 0.17903674
B31: Transferencias del Estado | C31: =IF(SUMIFS('Líneas codificadas'!$E$2:$E$49,'Líneas codificadas'!$A$2:$A$49,"Mega",'Líneas codificadas'!$B$2:$B$49,"FY2024")=0,"n.d.",SUMIFS('Líneas codificadas'!$E$2:$E$49,'Líneas codificadas'!$A$2:$A$49,"Mega",'Líneas codificadas'!$B$2:$B$49,"FY2024",'Líneas codificadas'!$O$2:$O$49,"Transferencias del Estado")/SUMIFS('Líneas codificadas'!$E$2:$E$49,'Líneas codificadas'!$A$2:$A$49,"Mega",'Líneas codificadas'!$B$2:$B$49,"FY2024")) -> 0 | D31: =IF(SUMIFS('Líneas codificadas'!$E$2:$E$49,'Líneas codificadas'!$A$2:$A$49,"Mega",'Líneas codificadas'!$B$2:$B$49,"FY2025")=0,"n.d.",SUMIFS('Líneas codificadas'!$E$2:$E$49,'Líneas codificadas'!$A$2:$A$49,"Mega",'Líneas codificadas'!$B$2:$B$49,"FY2025",'Líneas codificadas'!$O$2:$O$49,"Transferencias del Estado")/SUMIFS('Líneas codificadas'!$E$2:$E$49,'Líneas codificadas'!$A$2:$A$49,"Mega",'Líneas codificadas'!$B$2:$B$49,"FY2025")) -> 0 | E31: =IF(SUMIFS('Líneas codificadas'!$E$2:$E$49,'Líneas codificadas'!$A$2:$A$49,"Mega",'Líneas codificadas'!$B$2:$B$49,"H1 2025")=0,"n.d.",SUMIFS('Líneas codificadas'!$E$2:$E$49,'Líneas codificadas'!$A$2:$A$49,"Mega",'Líneas codificadas'!$B$2:$B$49,"H1 2025",'Líneas codificadas'!$O$2:$O$49,"Transferencias del Estado")/SUMIFS('Líneas codificadas'!$E$2:$E$49,'Líneas codificadas'!$A$2:$A$49,"Mega",'Líneas codificadas'!$B$2:$B$49,"H1 2025")) -> 0 | F31: =IF(SUMIFS('Líneas codificadas'!$E$2:$E$49,'Líneas codificadas'!$A$2:$A$49,"Mega",'Líneas codificadas'!$B$2:$B$49,"H1 2026")=0,"n.d.",SUMIFS('Líneas codificadas'!$E$2:$E$49,'Líneas codificadas'!$A$2:$A$49,"Mega",'Líneas codificadas'!$B$2:$B$49,"H1 2026",'Líneas codificadas'!$O$2:$O$49,"Transferencias del Estado")/SUMIFS('Líneas codificadas'!$E$2:$E$49,'Líneas codificadas'!$A$2:$A$49,"Mega",'Líneas codificadas'!$B$2:$B$49,"H1 2026")) -> 0
B32: Total | C32: =IF(SUMIFS('Líneas codificadas'!$E$2:$E$49,'Líneas codificadas'!$A$2:$A$49,"Mega",'Líneas codificadas'!$B$2:$B$49,"FY2024")=0,"n.d.",SUMIFS('Líneas codificadas'!$E$2:$E$49,'Líneas codificadas'!$A$2:$A$49,"Mega",'Líneas codificadas'!$B$2:$B$49,"FY2024")/SUMIFS('Líneas codificadas'!$E$2:$E$49,'Líneas codificadas'!$A$2:$A$49,"Mega",'Líneas codificadas'!$B$2:$B$49,"FY2024")) -> 1 | D32: =IF(SUMIFS('Líneas codificadas'!$E$2:$E$49,'Líneas codificadas'!$A$2:$A$49,"Mega",'Líneas codificadas'!$B$2:$B$49,"FY2025")=0,"n.d.",SUMIFS('Líneas codificadas'!$E$2:$E$49,'Líneas codificadas'!$A$2:$A$49,"Mega",'Líneas codificadas'!$B$2:$B$49,"FY2025")/SUMIFS('Líneas codificadas'!$E$2:$E$49,'Líneas codificadas'!$A$2:$A$49,"Mega",'Líneas codificadas'!$B$2:$B$49,"FY2025")) -> 1 | E32: =IF(SUMIFS('Líneas codificadas'!$E$2:$E$49,'Líneas codificadas'!$A$2:$A$49,"Mega",'Líneas codificadas'!$B$2:$B$49,"H1 2025")=0,"n.d.",SUMIFS('Líneas codificadas'!$E$2:$E$49,'Líneas codificadas'!$A$2:$A$49,"Mega",'Líneas codificadas'!$B$2:$B$49,"H1 2025")/SUMIFS('Líneas codificadas'!$E$2:$E$49,'Líneas codificadas'!$A$2:$A$49,"Mega",'Líneas codificadas'!$B$2:$B$49,"H1 2025")) -> 1 | F32: =IF(SUMIFS('Líneas codificadas'!$E$2:$E$49,'Líneas codificadas'!$A$2:$A$49,"Mega",'Líneas codificadas'!$B$2:$B$49,"H1 2026")=0,"n.d.",SUMIFS('Líneas codificadas'!$E$2:$E$49,'Líneas codificadas'!$A$2:$A$49,"Mega",'Líneas codificadas'!$B$2:$B$49,"H1 2026")/SUMIFS('Líneas codificadas'!$E$2:$E$49,'Líneas codificadas'!$A$2:$A$49,"Mega",'Líneas codificadas'!$B$2:$B$49,"H1 2026")) -> 1
A33: Chilevisión | B33: Publicidad | C33: =IF(SUMIFS('Líneas codificadas'!$E$2:$E$49,'Líneas codificadas'!$A$2:$A$49,"Chilevisión",'Líneas codificadas'!$B$2:$B$49,"FY2024")=0,"n.d.",SUMIFS('Líneas codificadas'!$E$2:$E$49,'Líneas codificadas'!$A$2:$A$49,"Chilevisión",'Líneas codificadas'!$B$2:$B$49,"FY2024",'Líneas codificadas'!$O$2:$O$49,"Publicidad")/SUMIFS('Líneas codificadas'!$E$2:$E$49,'Líneas codificadas'!$A$2:$A$49,"Chilevisión",'Líneas codificadas'!$B$2:$B$49,"FY2024")) -> 0.91045902 | D33: =IF(SUMIFS('Líneas codificadas'!$E$2:$E$49,'Líneas codificadas'!$A$2:$A$49,"Chilevisión",'Líneas codificadas'!$B$2:$B$49,"FY2025")=0,"n.d.",SUMIFS('Líneas codificadas'!$E$2:$E$49,'Líneas codificadas'!$A$2:$A$49,"Chilevisión",'Líneas codificadas'!$B$2:$B$49,"FY2025",'Líneas codificadas'!$O$2:$O$49,"Publicidad")/SUMIFS('Líneas codificadas'!$E$2:$E$49,'Líneas codificadas'!$A$2:$A$49,"Chilevisión",'Líneas codificadas'!$B$2:$B$49,"FY2025")) -> 0.89632396 | E33: =IF(SUMIFS('Líneas codificadas'!$E$2:$E$49,'Líneas codificadas'!$A$2:$A$49,"Chilevisión",'Líneas codificadas'!$B$2:$B$49,"H1 2025")=0,"n.d.",SUMIFS('Líneas codificadas'!$E$2:$E$49,'Líneas codificadas'!$A$2:$A$49,"Chilevisión",'Líneas codificadas'!$B$2:$B$49,"H1 2025",'Líneas codificadas'!$O$2:$O$49,"Publicidad")/SUMIFS('Líneas codificadas'!$E$2:$E$49,'Líneas codificadas'!$A$2:$A$49,"Chilevisión",'Líneas codificadas'!$B$2:$B$49,"H1 2025")) -> 0.95082266 | F33: =IF(SUMIFS('Líneas codificadas'!$E$2:$E$49,'Líneas codificadas'!$A$2:$A$49,"Chilevisión",'Líneas codificadas'!$B$2:$B$49,"H1 2026")=0,"n.d.",SUMIFS('Líneas codificadas'!$E$2:$E$49,'Líneas codificadas'!$A$2:$A$49,"Chilevisión",'Líneas codificadas'!$B$2:$B$49,"H1 2026",'Líneas codificadas'!$O$2:$O$49,"Publicidad")/SUMIFS('Líneas codificadas'!$E$2:$E$49,'Líneas codificadas'!$A$2:$A$49,"Chilevisión",'Líneas codificadas'!$B$2:$B$49,"H1 2026")) -> 0.9089824
B34: Otros ingresos operacionales | C34: =IF(SUMIFS('Líneas codificadas'!$E$2:$E$49,'Líneas codificadas'!$A$2:$A$49,"Chilevisión",'Líneas codificadas'!$B$2:$B$49,"FY2024")=0,"n.d.",SUMIFS('Líneas codificadas'!$E$2:$E$49,'Líneas codificadas'!$A$2:$A$49,"Chilevisión",'Líneas codificadas'!$B$2:$B$49,"FY2024",'Líneas codificadas'!$O$2:$O$49,"Otros ingresos operacionales")/SUMIFS('Líneas codificadas'!$E$2:$E$49,'Líneas codificadas'!$A$2:$A$49,"Chilevisión",'Líneas codificadas'!$B$2:$B$49,"FY2024")) -> 0.089540978 | D34: =IF(SUMIFS('Líneas codificadas'!$E$2:$E$49,'Líneas codificadas'!$A$2:$A$49,"Chilevisión",'Líneas codificadas'!$B$2:$B$49,"FY2025")=0,"n.d.",SUMIFS('Líneas codificadas'!$E$2:$E$49,'Líneas codificadas'!$A$2:$A$49,"Chilevisión",'Líneas codificadas'!$B$2:$B$49,"FY2025",'Líneas codificadas'!$O$2:$O$49,"Otros ingresos operacionales")/SUMIFS('Líneas codificadas'!$E$2:$E$49,'Líneas codificadas'!$A$2:$A$49,"Chilevisión",'Líneas codificadas'!$B$2:$B$49,"FY2025")) -> 0.10367604 | E34: =IF(SUMIFS('Líneas codificadas'!$E$2:$E$49,'Líneas codificadas'!$A$2:$A$49,"Chilevisión",'Líneas codificadas'!$B$2:$B$49,"H1 2025")=0,"n.d.",SUMIFS('Líneas codificadas'!$E$2:$E$49,'Líneas codificadas'!$A$2:$A$49,"Chilevisión",'Líneas codificadas'!$B$2:$B$49,"H1 2025",'Líneas codificadas'!$O$2:$O$49,"Otros ingresos operacionales")/SUMIFS('Líneas codificadas'!$E$2:$E$49,'Líneas codificadas'!$A$2:$A$49,"Chilevisión",'Líneas codificadas'!$B$2:$B$49,"H1 2025")) -> 0.049177343 | F34: =IF(SUMIFS('Líneas codificadas'!$E$2:$E$49,'Líneas codificadas'!$A$2:$A$49,"Chilevisión",'Líneas codificadas'!$B$2:$B$49,"H1 2026")=0,"n.d.",SUMIFS('Líneas codificadas'!$E$2:$E$49,'Líneas codificadas'!$A$2:$A$49,"Chilevisión",'Líneas codificadas'!$B$2:$B$49,"H1 2026",'Líneas codificadas'!$O$2:$O$49,"Otros ingresos operacionales")/SUMIFS('Líneas codificadas'!$E$2:$E$49,'Líneas codificadas'!$A$2:$A$49,"Chilevisión",'Líneas codificadas'!$B$2:$B$49,"H1 2026")) -> 0.091017596
B35: Transferencias del Estado | C35: =IF(SUMIFS('Líneas codificadas'!$E$2:$E$49,'Líneas codificadas'!$A$2:$A$49,"Chilevisión",'Líneas codificadas'!$B$2:$B$49,"FY2024")=0,"n.d.",SUMIFS('Líneas codificadas'!$E$2:$E$49,'Líneas codificadas'!$A$2:$A$49,"Chilevisión",'Líneas codificadas'!$B$2:$B$49,"FY2024",'Líneas codificadas'!$O$2:$O$49,"Transferencias del Estado")/SUMIFS('Líneas codificadas'!$E$2:$E$49,'Líneas codificadas'!$A$2:$A$49,"Chilevisión",'Líneas codificadas'!$B$2:$B$49,"FY2024")) -> 0 | D35: =IF(SUMIFS('Líneas codificadas'!$E$2:$E$49,'Líneas codificadas'!$A$2:$A$49,"Chilevisión",'Líneas codificadas'!$B$2:$B$49,"FY2025")=0,"n.d.",SUMIFS('Líneas codificadas'!$E$2:$E$49,'Líneas codificadas'!$A$2:$A$49,"Chilevisión",'Líneas codificadas'!$B$2:$B$49,"FY2025",'Líneas codificadas'!$O$2:$O$49,"Transferencias del Estado")/SUMIFS('Líneas codificadas'!$E$2:$E$49,'Líneas codificadas'!$A$2:$A$49,"Chilevisión",'Líneas codificadas'!$B$2:$B$49,"FY2025")) -> 0 | E35: =IF(SUMIFS('Líneas codificadas'!$E$2:$E$49,'Líneas codificadas'!$A$2:$A$49,"Chilevisión",'Líneas codificadas'!$B$2:$B$49,"H1 2025")=0,"n.d.",SUMIFS('Líneas codificadas'!$E$2:$E$49,'Líneas codificadas'!$A$2:$A$49,"Chilevisión",'Líneas codificadas'!$B$2:$B$49,"H1 2025",'Líneas codificadas'!$O$2:$O$49,"Transferencias del Estado")/SUMIFS('Líneas codificadas'!$E$2:$E$49,'Líneas codificadas'!$A$2:$A$49,"Chilevisión",'Líneas codificadas'!$B$2:$B$49,"H1 2025")) -> 0 | F35: =IF(SUMIFS('Líneas codificadas'!$E$2:$E$49,'Líneas codificadas'!$A$2:$A$49,"Chilevisión",'Líneas codificadas'!$B$2:$B$49,"H1 2026")=0,"n.d.",SUMIFS('Líneas codificadas'!$E$2:$E$49,'Líneas codificadas'!$A$2:$A$49,"Chilevisión",'Líneas codificadas'!$B$2:$B$49,"H1 2026",'Líneas codificadas'!$O$2:$O$49,"Transferencias del Estado")/SUMIFS('Líneas codificadas'!$E$2:$E$49,'Líneas codificadas'!$A$2:$A$49,"Chilevisión",'Líneas codificadas'!$B$2:$B$49,"H1 2026")) -> 0
B36: Total | C36: =IF(SUMIFS('Líneas codificadas'!$E$2:$E$49,'Líneas codificadas'!$A$2:$A$49,"Chilevisión",'Líneas codificadas'!$B$2:$B$49,"FY2024")=0,"n.d.",SUMIFS('Líneas codificadas'!$E$2:$E$49,'Líneas codificadas'!$A$2:$A$49,"Chilevisión",'Líneas codificadas'!$B$2:$B$49,"FY2024")/SUMIFS('Líneas codificadas'!$E$2:$E$49,'Líneas codificadas'!$A$2:$A$49,"Chilevisión",'Líneas codificadas'!$B$2:$B$49,"FY2024")) -> 1 | D36: =IF(SUMIFS('Líneas codificadas'!$E$2:$E$49,'Líneas codificadas'!$A$2:$A$49,"Chilevisión",'Líneas codificadas'!$B$2:$B$49,"FY2025")=0,"n.d.",SUMIFS('Líneas codificadas'!$E$2:$E$49,'Líneas codificadas'!$A$2:$A$49,"Chilevisión",'Líneas codificadas'!$B$2:$B$49,"FY2025")/SUMIFS('Líneas codificadas'!$E$2:$E$49,'Líneas codificadas'!$A$2:$A$49,"Chilevisión",'Líneas codificadas'!$B$2:$B$49,"FY2025")) -> 1 | E36: =IF(SUMIFS('Líneas codificadas'!$E$2:$E$49,'Líneas codificadas'!$A$2:$A$49,"Chilevisión",'Líneas codificadas'!$B$2:$B$49,"H1 2025")=0,"n.d.",SUMIFS('Líneas codificadas'!$E$2:$E$49,'Líneas codificadas'!$A$2:$A$49,"Chilevisión",'Líneas codificadas'!$B$2:$B$49,"H1 2025")/SUMIFS('Líneas codificadas'!$E$2:$E$49,'Líneas codificadas'!$A$2:$A$49,"Chilevisión",'Líneas codificadas'!$B$2:$B$49,"H1 2025")) -> 1 | F36: =IF(SUMIFS('Líneas codificadas'!$E$2:$E$49,'Líneas codificadas'!$A$2:$A$49,"Chilevisión",'Líneas codificadas'!$B$2:$B$49,"H1 2026")=0,"n.d.",SUMIFS('Líneas codificadas'!$E$2:$E$49,'Líneas codificadas'!$A$2:$A$49,"Chilevisión",'Líneas codificadas'!$B$2:$B$49,"H1 2026")/SUMIFS('Líneas codificadas'!$E$2:$E$49,'Líneas codificadas'!$A$2:$A$49,"Chilevisión",'Líneas codificadas'!$B$2:$B$49,"H1 2026")) -> 1
A38: NIVEL 2 — Común máximo (M$)
A39: Canal | B39: Categoría | C39: FY2024 | D39: FY2025 | E39: H1 2025 | F39: H1 2026
A40: TVN | B40: Publicidad | C40: =IF(SUMIFS('Líneas codificadas'!$E$2:$E$49,'Líneas codificadas'!$A$2:$A$49,"TVN",'Líneas codificadas'!$B$2:$B$49,"FY2024")=0,"n.d.",SUMIFS('Líneas codificadas'!$E$2:$E$49,'Líneas codificadas'!$A$2:$A$49,"TVN",'Líneas codificadas'!$B$2:$B$49,"FY2024",'Líneas codificadas'!$O$2:$O$49,"Publicidad")) -> 29763217 | D40: =IF(SUMIFS('Líneas codificadas'!$E$2:$E$49,'Líneas codificadas'!$A$2:$A$49,"TVN",'Líneas codificadas'!$B$2:$B$49,"FY2025")=0,"n.d.",SUMIFS('Líneas codificadas'!$E$2:$E$49,'Líneas codificadas'!$A$2:$A$49,"TVN",'Líneas codificadas'!$B$2:$B$49,"FY2025",'Líneas codificadas'!$O$2:$O$49,"Publicidad")) -> 28787675 | E40: =IF(SUMIFS('Líneas codificadas'!$E$2:$E$49,'Líneas codificadas'!$A$2:$A$49,"TVN",'Líneas codificadas'!$B$2:$B$49,"H1 2025")=0,"n.d.",SUMIFS('Líneas codificadas'!$E$2:$E$49,'Líneas codificadas'!$A$2:$A$49,"TVN",'Líneas codificadas'!$B$2:$B$49,"H1 2025",'Líneas codificadas'!$O$2:$O$49,"Publicidad")) -> 14095458 | F40: =IF(SUMIFS('Líneas codificadas'!$E$2:$E$49,'Líneas codificadas'!$A$2:$A$49,"TVN",'Líneas codificadas'!$B$2:$B$49,"H1 2026")=0,"n.d.",SUMIFS('Líneas codificadas'!$E$2:$E$49,'Líneas codificadas'!$A$2:$A$49,"TVN",'Líneas codificadas'!$B$2:$B$49,"H1 2026",'Líneas codificadas'!$O$2:$O$49,"Publicidad")) -> 12596474
B41: Otros ingresos operacionales | C41: =IF(SUMIFS('Líneas codificadas'!$E$2:$E$49,'Líneas codificadas'!$A$2:$A$49,"TVN",'Líneas codificadas'!$B$2:$B$49,"FY2024")=0,"n.d.",SUMIFS('Líneas codificadas'!$E$2:$E$49,'Líneas codificadas'!$A$2:$A$49,"TVN",'Líneas codificadas'!$B$2:$B$49,"FY2024",'Líneas codificadas'!$O$2:$O$49,"Otros ingresos operacionales")) -> 17086817 | D41: =IF(SUMIFS('Líneas codificadas'!$E$2:$E$49,'Líneas codificadas'!$A$2:$A$49,"TVN",'Líneas codificadas'!$B$2:$B$49,"FY2025")=0,"n.d.",SUMIFS('Líneas codificadas'!$E$2:$E$49,'Líneas codificadas'!$A$2:$A$49,"TVN",'Líneas codificadas'!$B$2:$B$49,"FY2025",'Líneas codificadas'!$O$2:$O$49,"Otros ingresos operacionales")) -> 17127723 | E41: =IF(SUMIFS('Líneas codificadas'!$E$2:$E$49,'Líneas codificadas'!$A$2:$A$49,"TVN",'Líneas codificadas'!$B$2:$B$49,"H1 2025")=0,"n.d.",SUMIFS('Líneas codificadas'!$E$2:$E$49,'Líneas codificadas'!$A$2:$A$49,"TVN",'Líneas codificadas'!$B$2:$B$49,"H1 2025",'Líneas codificadas'!$O$2:$O$49,"Otros ingresos operacionales")) -> 8141775 | F41: =IF(SUMIFS('Líneas codificadas'!$E$2:$E$49,'Líneas codificadas'!$A$2:$A$49,"TVN",'Líneas codificadas'!$B$2:$B$49,"H1 2026")=0,"n.d.",SUMIFS('Líneas codificadas'!$E$2:$E$49,'Líneas codificadas'!$A$2:$A$49,"TVN",'Líneas codificadas'!$B$2:$B$49,"H1 2026",'Líneas codificadas'!$O$2:$O$49,"Otros ingresos operacionales")) -> 7990951
B42: Transferencias del Estado | C42: =IF(SUMIFS('Líneas codificadas'!$E$2:$E$49,'Líneas codificadas'!$A$2:$A$49,"TVN",'Líneas codificadas'!$B$2:$B$49,"FY2024")=0,"n.d.",SUMIFS('Líneas codificadas'!$E$2:$E$49,'Líneas codificadas'!$A$2:$A$49,"TVN",'Líneas codificadas'!$B$2:$B$49,"FY2024",'Líneas codificadas'!$O$2:$O$49,"Transferencias del Estado")) -> 0 | D42: =IF(SUMIFS('Líneas codificadas'!$E$2:$E$49,'Líneas codificadas'!$A$2:$A$49,"TVN",'Líneas codificadas'!$B$2:$B$49,"FY2025")=0,"n.d.",SUMIFS('Líneas codificadas'!$E$2:$E$49,'Líneas codificadas'!$A$2:$A$49,"TVN",'Líneas codificadas'!$B$2:$B$49,"FY2025",'Líneas codificadas'!$O$2:$O$49,"Transferencias del Estado")) -> 2000000 | E42: =IF(SUMIFS('Líneas codificadas'!$E$2:$E$49,'Líneas codificadas'!$A$2:$A$49,"TVN",'Líneas codificadas'!$B$2:$B$49,"H1 2025")=0,"n.d.",SUMIFS('Líneas codificadas'!$E$2:$E$49,'Líneas codificadas'!$A$2:$A$49,"TVN",'Líneas codificadas'!$B$2:$B$49,"H1 2025",'Líneas codificadas'!$O$2:$O$49,"Transferencias del Estado")) -> 2000000 | F42: =IF(SUMIFS('Líneas codificadas'!$E$2:$E$49,'Líneas codificadas'!$A$2:$A$49,"TVN",'Líneas codificadas'!$B$2:$B$49,"H1 2026")=0,"n.d.",SUMIFS('Líneas codificadas'!$E$2:$E$49,'Líneas codificadas'!$A$2:$A$49,"TVN",'Líneas codificadas'!$B$2:$B$49,"H1 2026",'Líneas codificadas'!$O$2:$O$49,"Transferencias del Estado")) -> 1703714
B43: Total | C43: =IF(SUMIFS('Líneas codificadas'!$E$2:$E$49,'Líneas codificadas'!$A$2:$A$49,"TVN",'Líneas codificadas'!$B$2:$B$49,"FY2024")=0,"n.d.",SUMIFS('Líneas codificadas'!$E$2:$E$49,'Líneas codificadas'!$A$2:$A$49,"TVN",'Líneas codificadas'!$B$2:$B$49,"FY2024")) -> 46850034 | D43: =IF(SUMIFS('Líneas codificadas'!$E$2:$E$49,'Líneas codificadas'!$A$2:$A$49,"TVN",'Líneas codificadas'!$B$2:$B$49,"FY2025")=0,"n.d.",SUMIFS('Líneas codificadas'!$E$2:$E$49,'Líneas codificadas'!$A$2:$A$49,"TVN",'Líneas codificadas'!$B$2:$B$49,"FY2025")) -> 47915398 | E43: =IF(SUMIFS('Líneas codificadas'!$E$2:$E$49,'Líneas codificadas'!$A$2:$A$49,"TVN",'Líneas codificadas'!$B$2:$B$49,"H1 2025")=0,"n.d.",SUMIFS('Líneas codificadas'!$E$2:$E$49,'Líneas codificadas'!$A$2:$A$49,"TVN",'Líneas codificadas'!$B$2:$B$49,"H1 2025")) -> 24237233 | F43: =IF(SUMIFS('Líneas codificadas'!$E$2:$E$49,'Líneas codificadas'!$A$2:$A$49,"TVN",'Líneas codificadas'!$B$2:$B$49,"H1 2026")=0,"n.d.",SUMIFS('Líneas codificadas'!$E$2:$E$49,'Líneas codificadas'!$A$2:$A$49,"TVN",'Líneas codificadas'!$B$2:$B$49,"H1 2026")) -> 22291139
...

Sheet Tabla Napoli (rangos)
A1: Composición de ingresos de la TV abierta chilena en rangos (piso – techo), a la manera de Napoli (2003), Tabla 1.1
A2: Los rangos reflejan líneas de la nota de ingresos que mezclan categorías (ver 'Líneas codificadas'). Cuando piso = techo, la clasificación es exacta. Todas las cifras provienen de estados financieros (CMF).
A4: % venta de audiencias
A5: Canal | B5: FY2024 | C5: FY2025 | D5: H1 2025 | E5: H1 2026 | F5: Nota
A6: TVN | B6: =IF(Rangos!N10=Rangos!O10,TEXT(Rangos!N10,"0.0%"),TEXT(Rangos!N10,"0.0%")&" – "&TEXT(Rangos!O10,"0.0%")) -> 63.5% – 100.0% | C6: =IF(Rangos!N11=Rangos!O11,TEXT(Rangos!N11,"0.0%"),TEXT(Rangos!N11,"0.0%")&" – "&TEXT(Rangos!O11,"0.0%")) -> 60.1% – 95.8% | D6: =IF(Rangos!N12=Rangos!O12,TEXT(Rangos!N12,"0.0%"),TEXT(Rangos!N12,"0.0%")&" – "&TEXT(Rangos!O12,"0.0%")) -> 58.2% – 91.7% | E6: =IF(Rangos!N13=Rangos!O13,TEXT(Rangos!N13,"0.0%"),TEXT(Rangos!N13,"0.0%")&" – "&TEXT(Rangos!O13,"0.0%")) -> 56.5% – 92.4% | F6: EEFF. Piso = publicidad TV abierta; techo suma 'otros ingresos' (podría contener publicidad digital). Subvención NTV aislada como Fuera (2025–26).
A7: Canal 13 | B7: =IF(Rangos!N2=Rangos!O2,TEXT(Rangos!N2,"0.0%"),TEXT(Rangos!N2,"0.0%")&" – "&TEXT(Rangos!O2,"0.0%")) -> 76.0% | C7: =IF(Rangos!N3=Rangos!O3,TEXT(Rangos!N3,"0.0%"),TEXT(Rangos!N3,"0.0%")&" – "&TEXT(Rangos!O3,"0.0%")) -> 76.7% | D7: =IF(Rangos!N4=Rangos!O4,TEXT(Rangos!N4,"0.0%"),TEXT(Rangos!N4,"0.0%")&" – "&TEXT(Rangos!O4,"0.0%")) -> 75.7% | E7: =IF(Rangos!N5=Rangos!O5,TEXT(Rangos!N5,"0.0%"),TEXT(Rangos!N5,"0.0%")&" – "&TEXT(Rangos!O5,"0.0%")) -> 70.9% | F7: Audiencias exacta (dos líneas puras). La incertidumbre está entre Contenidos y Fuera (arriendos, venta de activos).
A8: Mega | B8: =IF(Rangos!N6=Rangos!O6,TEXT(Rangos!N6,"0.0%"),TEXT(Rangos!N6,"0.0%")&" – "&TEXT(Rangos!O6,"0.0%")) -> 75.7% | C8: =IF(Rangos!N7=Rangos!O7,TEXT(Rangos!N7,"0.0%"),TEXT(Rangos!N7,"0.0%")&" – "&TEXT(Rangos!O7,"0.0%")) -> 78.9% | D8: =IF(Rangos!N14=Rangos!O14,TEXT(Rangos!N14,"0.0%"),TEXT(Rangos!N14,"0.0%")&" – "&TEXT(Rangos!O14,"0.0%")) -> 72.6% | E8: =IF(Rangos!N16=Rangos!O16,TEXT(Rangos!N16,"0.0%"),TEXT(Rangos!N16,"0.0%")&" – "&TEXT(Rangos!O16,"0.0%")) -> 82.1% | F8: Exacto (tres líneas puras). Incluye radios y cable; ver fila de perímetro TV.
A9: Chilevisión | B9: =IF(Rangos!N8=Rangos!O8,TEXT(Rangos!N8,"0.0%"),TEXT(Rangos!N8,"0.0%")&" – "&TEXT(Rangos!O8,"0.0%")) -> 91.0% – 100.0% | C9: =IF(Rangos!N9=Rangos!O9,TEXT(Rangos!N9,"0.0%"),TEXT(Rangos!N9,"0.0%")&" – "&TEXT(Rangos!O9,"0.0%")) -> 89.6% – 100.0% | D9: =IF(Rangos!N17=Rangos!O17,TEXT(Rangos!N17,"0.0%"),TEXT(Rangos!N17,"0.0%")&" – "&TEXT(Rangos!O17,"0.0%")) -> 95.1% – 100.0% | E9: =IF(Rangos!N19=Rangos!O19,TEXT(Rangos!N19,"0.0%"),TEXT(Rangos!N19,"0.0%")&" – "&TEXT(Rangos!O19,"0.0%")) -> 90.9% – 100.0% | F9: 'Nuevos negocios' mezcla publicidad digital, señales/contenido, fees y concursos → rango en las tres categorías. H1-2025 según comparativo 2026 (reclasificado).
A11: % venta de contenidos
A12: Canal | B12: FY2024 | C12: FY2025 | D12: H1 2025 | E12: H1 2026
A13: TVN | B13: =IF(Rangos!P10=Rangos!Q10,TEXT(Rangos!P10,"0.0%"),TEXT(Rangos!P10,"0.0%")&" – "&TEXT(Rangos!Q10,"0.0%")) -> 0.0% – 36.5% | C13: =IF(Rangos!P11=Rangos!Q11,TEXT(Rangos!P11,"0.0%"),TEXT(Rangos!P11,"0.0%")&" – "&TEXT(Rangos!Q11,"0.0%")) -> 0.0% – 35.7% | D13: =IF(Rangos!P12=Rangos!Q12,TEXT(Rangos!P12,"0.0%"),TEXT(Rangos!P12,"0.0%")&" – "&TEXT(Rangos!Q12,"0.0%")) -> 0.0% – 33.6% | E13: =IF(Rangos!P13=Rangos!Q13,TEXT(Rangos!P13,"0.0%"),TEXT(Rangos!P13,"0.0%")&" – "&TEXT(Rangos!Q13,"0.0%")) -> 0.0% – 35.8%
A14: Canal 13 | B14: =IF(Rangos!P2=Rangos!Q2,TEXT(Rangos!P2,"0.0%"),TEXT(Rangos!P2,"0.0%")&" – "&TEXT(Rangos!Q2,"0.0%")) -> 0.0% – 24.0% | C14: =IF(Rangos!P3=Rangos!Q3,TEXT(Rangos!P3,"0.0%"),TEXT(Rangos!P3,"0.0%")&" – "&TEXT(Rangos!Q3,"0.0%")) -> 0.0% – 23.3% | D14: =IF(Rangos!P4=Rangos!Q4,TEXT(Rangos!P4,"0.0%"),TEXT(Rangos!P4,"0.0%")&" – "&TEXT(Rangos!Q4,"0.0%")) -> 0.0% – 24.3% | E14: =IF(Rangos!P5=Rangos!Q5,TEXT(Rangos!P5,"0.0%"),TEXT(Rangos!P5,"0.0%")&" – "&TEXT(Rangos!Q5,"0.0%")) -> 0.0% – 29.1%
